Workbook

Sheet 00_Workbook_Guide
A1: Babysteps Platform Requirements Workbook
A3: Item | B3: Specification
A4: Purpose | B4: Implementation-ready requirements specification for Codex-assisted development of the Babysteps platform and its learning-app integrations.
A5: Approval rule | B5: A requirement is added to 02_Requirements only after it has been visualized and explicitly approved.
A6: Priority model | B6: Must Have = required for the target release. Should Have = valuable but may follow after the must-have foundation.
A7: Requirement granularity | B7: Each row must describe one independently testable behavior or constraint.
A8: Traceability | B8: Requirement IDs connect UX flows, API contracts, data-model entries, acceptance tests, and implementation notes.
A9: Platform boundary | B9: Babysteps owns identity, parent-owned learner profiles, app access, purchaser-parent subscriptions, shared engagement, progress persistence, privacy and administration.
A10: Codex readiness | B10: A requirement is Codex Ready only when 09_Codex_Build_Specs contains an Approved exact build packet covering runtime assumptions, functional contract, UI, migrations, APIs, validation, authorization, security, errors, idempotency, telemetry, tests, explicit non-goals, files/modules and definition of done.
A11: Codex readiness | B11: A requirement is Codex Ready only when behavior, acceptance criteria, dependencies, data/API impact, edge cases, and security expectations are complete.
A12: Current stage | B12: Twelve active requirements are frozen and Codex Ready. BB-04 is 2/4 complete: secure one-time app launch and short-lived dual-proof backend API authorization with no browser token or refresh token.
A13: Commercial and cadence constraints | B13: Every subscription is purchased by one parent and assigned to one learner. Products may grant one app or a bundle. Each entitled learner receives two learning sessions per week independently in each entitled app.
A14: Step-by-step workflow
A15: 1 | B15: Select one feature group | C15: Define the learner/business outcome
A16: 2 | B16: Visualize proposed requirements in chat | C16: Show actors, screens, states, rules, data and edge cases
A17: 3 | B17: Challenge and refine | C17: Remove duplication, hidden complexity and app/platform boundary violations
A18: 4 | B18: Approve individual requirements | C18: Confirm Must Have or Should Have
A19: 5 | B19: Write approved requirements | C19: Populate requirement, UX, API, data and test sheets
A20: 6 | B20: Generate Codex build packet | C20: Export a coherent development slice with dependencies and tests
A22: This workbook is intentionally empty of product requirements until each requirement is visualized and approved.

Sheet 01_Dashboard
A1: Babysteps Requirements Dashboard
A3: Portfolio metric | B3: Current | D3: Building block | E3: Planned | F3: Frozen | G3: Remaining | H3: Complete
A4: Frozen requirements | B4: 12 | D4: ='01A_Requirement_Roadmap'!D5 -> Identity and authentication | E4: ='01A_Requirement_Roadmap'!E5 -> 4 | F4: ='01A_Requirement_Roadmap'!F5 -> 4 | G4: ='01A_Requirement_Roadmap'!G5 -> 0 | H4: ='01A_Requirement_Roadmap'!H5 -> 1
A5: Remaining requirements | B5: 62 | D5: ='01A_Requirement_Roadmap'!D6 -> Learner profiles and guardians | E5: ='01A_Requirement_Roadmap'!E6 -> 3 | F5: ='01A_Requirement_Roadmap'!F6 -> 3 | G5: ='01A_Requirement_Roadmap'!G6 -> 0 | H5: ='01A_Requirement_Roadmap'!H6 -> 1
A6: Planned requirements | B6: 74 | D6: ='01A_Requirement_Roadmap'!D7 -> App registry | E6: ='01A_Requirement_Roadmap'!E7 -> 2 | F6: ='01A_Requirement_Roadmap'!F7 -> 2 | G6: ='01A_Requirement_Roadmap'!G7 -> 0 | H6: ='01A_Requirement_Roadmap'!H7 -> 1
A7: Overall completion | B7: 0.16216216 | D7: ='01A_Requirement_Roadmap'!D8 -> App launch and single sign-on | E7: ='01A_Requirement_Roadmap'!E8 -> 4 | F7: ='01A_Requirement_Roadmap'!F8 -> 2 | G7: ='01A_Requirement_Roadmap'!G8 -> 2 | H7: ='01A_Requirement_Roadmap'!H8 -> 0.5
A8: Must Haves frozen | B8: 11 | D8: ='01A_Requirement_Roadmap'!D9 -> Authorization | E8: ='01A_Requirement_Roadmap'!E9 -> 4 | F8: ='01A_Requirement_Roadmap'!F9 -> 3 | G8: ='01A_Requirement_Roadmap'!G9 -> 1 | H8: ='01A_Requirement_Roadmap'!H9 -> 0.75
A9: Should Haves frozen | B9: 0 | D9: ='01A_Requirement_Roadmap'!D10 -> Active session control | E9: ='01A_Requirement_Roadmap'!E10 -> 3 | F9: ='01A_Requirement_Roadmap'!F10 -> 3 | G9: ='01A_Requirement_Roadmap'!G10 -> 0 | H9: ='01A_Requirement_Roadmap'!H10 -> 1
A10: Codex Ready | B10: 12 | D10: ='01A_Requirement_Roadmap'!D11 -> Billing and subscriptions | E10: ='01A_Requirement_Roadmap'!E11 -> 5 | F10: ='01A_Requirement_Roadmap'!F11 -> 5 | G10: ='01A_Requirement_Roadmap'!G11 -> 0 | H10: ='01A_Requirement_Roadmap'!H11 -> 1
A11: Building blocks complete | B11: 3 | D11: ='01A_Requirement_Roadmap'!D12 -> Entitlements and app access | E11: ='01A_Requirement_Roadmap'!E12 -> 4 | F11: ='01A_Requirement_Roadmap'!F12 -> 4 | G11: ='01A_Requirement_Roadmap'!G12 -> 0 | H11: ='01A_Requirement_Roadmap'!H12 -> 1
A12: Building blocks in progress | B12: 2 | D12: ='01A_Requirement_Roadmap'!D13 -> Progress storage and synchronization | E12: ='01A_Requirement_Roadmap'!E13 -> 5 | F12: ='01A_Requirement_Roadmap'!F13 -> 4 | G12: ='01A_Requirement_Roadmap'!G13 -> 1 | H12: ='01A_Requirement_Roadmap'!H13 -> 0.8
A13: Nice to Haves frozen | B13: =COUNTIFS('02_Requirements'!$F$2:$F$1000,"Nice to Have",'02_Requirements'!$G$2:$G$1000,"Approved") -> 1 | D13: ='01A_Requirement_Roadmap'!D14 -> Unified learner launcher | E13: ='01A_Requirement_Roadmap'!E14 -> 4 | F13: ='01A_Requirement_Roadmap'!F14 -> 1 | G13: ='01A_Requirement_Roadmap'!G14 -> 3 | H13: ='01A_Requirement_Roadmap'!H14 -> 0.25
A14: Deferred requirements | B14: =COUNTIF('02_Requirements'!$G$2:$G$1000,"Deferred") -> 7 | D14: ='01A_Requirement_Roadmap'!D15 -> Engagement and gamification | E14: ='01A_Requirement_Roadmap'!E15 -> 6 | F14: ='01A_Requirement_Roadmap'!F15 -> 0 | G14: ='01A_Requirement_Roadmap'!G15 -> 6 | H14: ='01A_Requirement_Roadmap'!H15 -> 0
D15: ='01A_Requirement_Roadmap'!D16 -> Parent dashboard | E15: ='01A_Requirement_Roadmap'!E16 -> 4 | F15: ='01A_Requirement_Roadmap'!F16 -> 0 | G15: ='01A_Requirement_Roadmap'!G16 -> 4 | H15: ='01A_Requirement_Roadmap'!H16 -> 0
D16: ='01A_Requirement_Roadmap'!D17 -> Notifications and reminders | E16: ='01A_Requirement_Roadmap'!E17 -> 3 | F16: ='01A_Requirement_Roadmap'!F17 -> 0 | G16: ='01A_Requirement_Roadmap'!G17 -> 3 | H16: ='01A_Requirement_Roadmap'!H17 -> 0
D17: ='01A_Requirement_Roadmap'!D18 -> Administration and support | E17: ='01A_Requirement_Roadmap'!E18 -> 5 | F17: ='01A_Requirement_Roadmap'!F18 -> 0 | G17: ='01A_Requirement_Roadmap'!G18 -> 5 | H17: ='01A_Requirement_Roadmap'!H18 -> 0
D18: ='01A_Requirement_Roadmap'!D19 -> Privacy, consent and child safety | E18: ='01A_Requirement_Roadmap'!E19 -> 5 | F18: ='01A_Requirement_Roadmap'!F19 -> 0 | G18: ='01A_Requirement_Roadmap'!G19 -> 5 | H18: ='01A_Requirement_Roadmap'!H19 -> 0
D19: ='01A_Requirement_Roadmap'!D20 -> Analytics and observability | E19: ='01A_Requirement_Roadmap'!E20 -> 4 | F19: ='01A_Requirement_Roadmap'!F20 -> 1 | G19: ='01A_Requirement_Roadmap'!G20 -> 3 | H19: ='01A_Requirement_Roadmap'!H20 -> 0.25
D20: ='01A_Requirement_Roadmap'!D21 -> Developer platform and SDK | E20: ='01A_Requirement_Roadmap'!E21 -> 5 | F20: ='01A_Requirement_Roadmap'!F21 -> 0 | G20: ='01A_Requirement_Roadmap'!G21 -> 5 | H20: ='01A_Requirement_Roadmap'!H21 -> 0
D21: ='01A_Requirement_Roadmap'!D22 -> Backup, recovery and deployment safety | E21: ='01A_Requirement_Roadmap'!E22 -> 4 | F21: ='01A_Requirement_Roadmap'!F22 -> 0 | G21: ='01A_Requirement_Roadmap'!G22 -> 4 | H21: ='01A_Requirement_Roadmap'!H22 -> 0

Sheet 02_Requirements
A1: Requirement ID | B1: Epic ID | C1: Domain | D1: Feature Group | E1: Requirement Title | F1: Priority | G1: Approval Status | H1: Codex Ready | I1: Delivery Status | J1: Requirement Type | K1: Ownership Layer | L1: Primary Actor | M1: User Story | N1: Functional Requirement | O1: Business Rules | P1: Preconditions | Q1: Trigger | R1: Main Flow | S1: Alternate / Error Flows | T1: Data Inputs | U1: Data Outputs | V1: UI / UX Specification | W1: API / Service Contract | X1: Data Model Impact | Y1: Security & Privacy | Z1: Non-Functional Requirements | AA1: Acceptance Criteria Summary | AB1: Dependencies | AC1: Duolingo Inspiration | AD1: Source URL | AE1: Codex Implementation Notes | AF1: Test IDs | AG1: Version | AH1: Owner | AI1: Last Updated
A2: IA-001 | B2: EP-IDENTITY-01 | C2: Identity & Access | D2: Parent Registration & Login | E2: Email-and-password parent registration and login | F2: Must Have | G2: Approved | H2: Yes | I2: Done | J2: Functional | K2: Babysteps Platform | L2: Parent | M2: As a parent, I want to register and sign in using my email address and password so that I can securely access Babysteps and manage my children's learning profiles. | N2: Babysteps shall support parent account registration and login using only email address and password in Version 1. Immediately after Supabase Auth successfully creates the user, the platform shall create exactly one parent profile linked one-to-one with that Auth user. The profile may exist while email verification is pending, but protected parent and learner data shall remain inaccessible until the email is verified. Profile creation shall be idempotent and recoverable. | O2: 1. Version 1 supports email and password only; Google, Apple, phone and magic-link authentication are excluded. 2. Email is the unique login identifier and is normalized before submission. 3. Password storage, hashing and verification remain entirely within Supabase Auth. 4. A parent profile is created immediately after the Auth user is created. 5. Email verification is required before protected parent or learner data can be accessed. 6. One Supabase Auth user maps to exactly one parent profile. 7. Repeated signup callbacks, triggers, refreshes or recovery calls must not create duplicate parent profiles. 8. Suspended or deleted profiles cannot access protected resources. 9. A child learner does not require an Auth user or email account. | P2: The visitor is not authenticated. The Babysteps Supabase project, authentication email provider and callback URLs are configured. | Q2: The visitor submits the registration form or login form. | R2: Registration: 1. Parent enters email, password and password confirmation. 2. Client and server validate the inputs. 3. Supabase Auth creates the authentication identity. 4. A database trigger or trusted server process creates the parent profile immediately with onboarding_status='profile_pending'. 5. A verification email is sent. 6. Parent verifies the email. 7. On first verified access, Babysteps confirms the existing profile and continues to parent-profile onboarding. Login: 1. Parent enters email and password. 2. Supabase Auth validates the credentials. 3. Babysteps checks email verification and parent profile status. 4. If the profile is unexpectedly missing, a recovery upsert creates it safely. 5. Parent enters the account area or resumes the next incomplete onboarding step. | S2: Existing email: direct the parent to Sign in or Forgot password without creating another account. Weak or invalid password: preserve the email and show validation feedback. Expired verification link: permit resend subject to rate limits. Profile creation interruption: retry the idempotent profile upsert on the next authenticated request. Incorrect credentials: show a generic authentication error. Suspended profile: deny protected access and show the support route. Expired session: return to sign-in and preserve the intended destination when safe. | T2: Registration inputs: email, password, password confirmation, accepted terms version and accepted privacy version. Login inputs: email and password. System context: Supabase Auth user ID, email verification status, locale and timezone defaults. | U2: Supabase Auth identity; exactly one parent profile created at registration; verification-pending or verified authentication state; onboarding status; authenticated session after verification; audit events for signup, profile creation, verification, login success/failure, password reset and logout. | V2: Separate Sign up and Sign in screens. Explicit Email, Password and Confirm password labels. Show/hide password control. Visible password requirements. Inline validation and loading state. Non-enumerating error messages. Post-registration verification-required screen. First verified login continues to onboarding rather than asking the user to register again. No Google, Apple, phone or magic-link controls in Version 1. | W2: Supabase Auth operations: - signUp(email, password) - signInWithPassword(email, password) - signOut() - resetPasswordForEmail(email) - updateUser(password) Profile creation: - Preferred: an idempotent database trigger on auth.users INSERT creates public.profiles using NEW.id. - Recovery endpoint: POST /v1/onboarding/ensure-parent-profile verifies the authenticated user and safely creates the profile only when it is missing. Protected routes require a verified Supabase session and an active parent profile. | X2: profiles table: - id uuid primary key referencing auth.users(id) on delete cascade - profile_type text default 'parent' - display_name text nullable until onboarding - account_status text - onboarding_status text default 'profile_pending' - locale text - timezone text - created_at timestamptz - updated_at timestamptz Allowed onboarding_status values: - profile_pending - learner_pending - complete Create an idempotent auth.users INSERT trigger that inserts the profile with ON CONFLICT DO NOTHING. Retain a server-side recovery upsert for repair and testability. | Y2: Passwords, password hashes and authentication tokens must never be stored in Babysteps tables or logs. Service-role credentials remain server-side. Require HTTPS and secure session cookies. Rate-limit signup, login, verification resend and password reset. Avoid account-enumeration messages. Require verified email before protected access. Record privacy and terms acceptance separately with policy version and timestamp. | Z2: Registration and login p95 server response under 2 seconds, excluding external email delivery. All flows keyboard accessible and usable at 320px width. Duplicate profile creation rate must be zero. Failures show a clear retry path. Logs include request IDs but exclude passwords and tokens. | AA2: AC1 Parent can register with a valid email and compliant password. AC2 Successful Auth registration immediately creates exactly one parent profile. AC3 A verification email is sent and protected data remains inaccessible until verification. AC4 First verified access uses the existing parent profile rather than creating another. AC5 Replayed triggers, callbacks and recovery calls do not create duplicate profiles. AC6 Parent can sign in and sign out. AC7 Parent can request and complete a password reset. AC8 Incorrect credentials do not reveal whether the email exists. AC9 Suspended or deleted profiles are denied protected access. AC10 No social, phone or magic-link authentication control appears in Version 1. | AB2: Supabase Auth configuration; custom SMTP before scaled onboarding; profiles migration; consent/privacy policy versions; authenticated route middleware; email templates. | AC2: Babysteps retains low-friction onboarding but deliberately uses a simpler email-password identity model for Version 1. | AE2: Implement the Auth UI and server actions as a reusable Babysteps identity module. Keep authentication behind an AuthAdapter interface so future providers can be added without changing parent IDs. Use shared input schemas for email/password validation. Create the parent profile from an idempotent auth.users INSERT trigger. Keep POST /v1/onboarding/ensure-parent-profile as a recovery operation and safe authenticated read. Redirect by onboarding_status after verification: - profile_pending -> parent profile completion - learner_pending -> add or select learner - complete -> dashboard Exact build packet: 09_Codex_Build_Specs!CBS-IA-001 | AF2: AT-IA-001-01, AT-IA-001-02, AT-IA-001-03, AT-IA-001-04, AT-IA-001-05, AT-IA-001-06, AT-IA-001-07, AT-IA-001-08, AT-IA-001-09 | AG2: 1.0 | AH2: Product Owner | AI2: 2026-07-30
A3: IA-002 | B3: EP-IDENTITY-01 | C3: Identity & Access | D3: Parent Profile Onboarding | E3: Mandatory parent mobile number with optional display name | F3: Must Have | G3: Approved | H3: Yes | I3: Done | J3: Functional | K3: Babysteps Platform | L3: Parent | M3: As a registered parent, I want to complete a minimal parent profile so that Babysteps can identify and contact me without collecting unnecessary personal information. | N3: After email verification, Babysteps shall require the parent to complete the existing parent profile by supplying a valid mobile number. The display name shall be optional. Mobile numbers shall be format-validated and normalized only; Version 1 shall not send or require an SMS OTP. Postal address and parent date of birth shall not be collected. Invoices and receipts shall be delivered to the authenticated email address. The invoice recipient label shall use the display name when present and the email address when the display name is absent. | O3: 1. The parent profile already exists before onboarding begins. 2. Mobile number is mandatory before the parent can continue to learner setup. 3. Mobile number must be parsed and validated using the selected country or calling code. 4. Store the normalized mobile number in E.164 format. 5. Version 1 performs format validation only; it does not send an SMS OTP and does not mark the number as verified. 6. Mobile number does not have to be globally unique because family members may share a contact number. 7. Display name is optional and may be blank. 8. Email is read-only and comes from Supabase Auth. 9. Postal address, parent date of birth and legal name are not collected in Version 1. 10. Invoices and receipts are sent to the authenticated email address. 11. Invoice recipient label uses display name when present; otherwise it uses the authenticated email address. 12. Mobile number use for marketing or SMS requires separate consent and is outside this requirement. 13. Successful completion changes onboarding_status from profile_pending to learner_pending. 14. Repeated submissions update the same profile and do not create duplicate consent records. | P3: The parent has a verified Supabase session, an active parent profile and onboarding_status='profile_pending'. Current Terms of Service and Privacy Policy versions are configured. | Q3: The verified parent enters or resumes parent-profile onboarding. | R3: 1. Load the existing parent profile and authenticated email. 2. Display email as read-only. 3. Parent selects or confirms the country calling code. 4. Parent enters a mobile number. 5. Parent may optionally enter a display name. 6. Parent accepts the current Terms and Privacy Policy. 7. Client and server validate the mobile number using country-aware rules. 8. Server stores the number in E.164 format and updates the existing profile. 9. Versioned policy acceptance records are written idempotently. 10. onboarding_status changes to learner_pending. 11. Continue directly to learner-profile creation. | S3: Invalid number: show country-aware validation feedback and retain entered values. Missing number: block submission. Display name omitted: allow submission and retain NULL. Profile already complete: redirect to the next incomplete onboarding step. Policy version changed: require acceptance of the current version. Save failure: preserve form state and allow retry. Expired session: return to login and resume the same step. Duplicate submission: update the existing profile and reuse consent records. Later number change: validate and audit; no OTP is required in Version 1. | T3: Authenticated email; optional display name; selected country/calling code; mandatory mobile number; accepted Terms version; accepted Privacy version; locale and timezone. | U3: Updated parent profile with phone_e164, optional display_name and onboarding_status='learner_pending'; consent records; audit event; invoice contact email and computed invoice recipient label. | V3: Display authenticated email as read-only. Show Parent name as optional. Show country/calling-code selector and mandatory Mobile number field. Explain that the number is format-validated but not SMS-verified. Provide inline country-aware validation. Show Terms and Privacy acceptance controls. Disable Continue until mandatory inputs are valid. Do not show address or date-of-birth fields. Preserve values and show Retry after a failed save. | W3: GET /v1/parent/profile returns authenticated email, profile fields, onboarding status and current policy versions. PATCH /v1/parent/profile accepts optional displayName, phoneCountryCode, mobileNumber, locale, timezone, acceptedTermsVersion and acceptedPrivacyVersion. The server validates and normalizes the number to E.164. It updates the profile, writes idempotent consent records and advances onboarding_status in one transaction. No endpoint sends or validates an SMS OTP in Version 1. invoiceRecipientLabel = non-empty trimmed display_name, otherwise authenticated email. | X3: profiles: - display_name text nullable - phone_e164 text nullable before onboarding; application-required after onboarding - phone_country_code text nullable - locale text not null default 'en-IN' - timezone text not null default 'Asia/Kolkata' - onboarding_status text consent_records: - id uuid primary key - parent_user_id uuid references profiles(id) - consent_type text - policy_version text - granted boolean - granted_at timestamptz - revoked_at timestamptz nullable - unique(parent_user_id, consent_type, policy_version) Do not add phone_verified_at, postal_address or parent_date_of_birth in Version 1. | Y3: Treat the mobile number as personal data. Return it only to the authenticated parent and authorized support/admin roles. Mask it in logs and support views. Do not use it for SMS, marketing or authentication without separate consent and requirements. Use a maintained phone-number parsing library rather than custom regular expressions alone. Email remains the invoice-delivery address and authentication identifier. Rate-limit profile updates. Store policy acceptance version and timestamp. | Z3: Profile load/update p95 under 1.5 seconds. Support international E.164-compatible numbers. Keyboard accessible and usable at 320px width. Profile and consent update must be transactional. No duplicate profile or consent records. Normalization is deterministic for the same valid input. | AA3: AC1 A verified parent with profile_pending is directed to onboarding. AC2 The existing profile is updated rather than duplicated. AC3 The parent cannot continue without a valid mobile number. AC4 A valid number is stored in E.164 format. AC5 No SMS OTP is sent or required. AC6 The parent can complete onboarding without a display name. AC7 Email is read-only and sourced from Supabase Auth. AC8 Terms and Privacy versions are recorded with timestamps. AC9 Completion advances onboarding_status to learner_pending. AC10 Postal address and parent date of birth are not requested or stored. AC11 Invoices are delivered to the authenticated email. AC12 Invoice label uses display name when present and email otherwise. AC13 Repeated submissions create no duplicate records. AC14 Failed saves preserve entered values and support retry. | AB3: IA-001; parent profile schema; consent schema; current Terms and Privacy versions; phone-number parsing library; learner-profile creation route; invoice template. | AC3: Uses brief progressive onboarding while deliberately limiting data collection. | AE3: Use a libphonenumber-compatible library for server validation and E.164 normalization. Do not enforce phone uniqueness. Keep phone_e164 nullable at database level because the profile exists before onboarding, but require it for learner_pending and complete states. Perform profile update, consent inserts and status transition transactionally. Do not create OTP UI, OTP tables, SMS integration or a verified-phone flag. Create one invoiceRecipientLabel utility returning display_name or authenticated email. Mask numbers in logs and administration screens. Exact build packet: 09_Codex_Build_Specs!CBS-IA-002 | AF3: AT-IA-002-01, AT-IA-002-02, AT-IA-002-03, AT-IA-002-04, AT-IA-002-05, AT-IA-002-06, AT-IA-002-07, AT-IA-002-08, AT-IA-002-09, AT-IA-002-10, AT-IA-002-11, AT-IA-002-12, AT-IA-002-13, AT-IA-002-14 | AG3: 1.0 | AH3: Product Owner | AI3: 2026-07-30
A4: IA-003 | B4: EP-IDENTITY-01 | C4: Identity & Access | D4: Account Security & Lifecycle | E4: Parent credential changes and soft account deletion | F4: Must Have | G4: Approved | H4: Yes | I4: Done | J4: Functional | K4: Babysteps Platform | L4: Parent | M4: As a parent, I want to safely change my password or login email and deactivate my account so that I can maintain control of my Babysteps identity without permanently deleting retained records. | N4: Babysteps shall allow an authenticated active parent to change the account password, request a login-email change and soft-delete the account. Email changes require current-password reauthentication and verification of the proposed new email. The verification link expires exactly 24 hours after issue. The current email remains active until verification succeeds. Immediately after successful verification, the new email becomes the authoritative login, invoice and receipt address, and the previous email is archived. Account deletion is a soft delete only: records remain in the database, all access is blocked and active sessions are revoked. Restoration is administrator-controlled and never self-service in Version 1. | O4: 1. Credential changes require an authenticated, verified and active parent profile. 2. The current password must be revalidated immediately before password change, email-change request or account soft deletion. 3. New passwords must meet the central policy, match confirmation and differ from the current password. 4. The new email must be normalized, valid, different from the current email and unused by another Auth identity. 5. Supabase Secure Email Change must be disabled so only the proposed new email requires verification. 6. Auth email-link expiry must be configured to 86,400 seconds. 7. While verification is pending, the current email remains the active login and invoice address. 8. On successful email verification, the new email activates immediately and the old email is archived. 9. Expired, cancelled or failed email changes leave the current email unchanged. 10. Only one pending email-change request may exist per parent. 11. Soft delete sets account_status='deleted', deleted_at and auth_revoked_before; it never physically deletes Auth, profile, learner, progress, consent, billing, invoice or audit records. 12. Soft deletion revokes all Babysteps parent, learner and app sessions. 13. Platform middleware denies deleted accounts even if a Supabase Auth session can still be established. 14. Deleted accounts cannot self-restore. An authorized platform administrator may restore the account, after which the parent must sign in again. 15. Every subscription belongs to its purchaser parent through purchaser_parent_id. Subscription cancellation and financial retention are governed by Billing; this requirement emits an account_soft_deleted event but does not silently delete financial records. | P4: IA-001 and IA-002 are implemented. The parent has a verified Supabase identity, an active profile and completed profile onboarding. Supabase email delivery and callback URLs are configured. | Q4: The parent opens Account Settings → Security, requests a password/email change, or confirms soft deletion. | R4: Password change: 1. Parent enters current password, new password and confirmation. 2. Server reauthenticates the current email/password using an isolated non-persistent Supabase client. 3. Server validates the new password. 4. Auth password is updated. 5. Success is shown and the action is audited. Email change: 1. Parent enters proposed email and current password. 2. Server reauthenticates and validates uniqueness/format. 3. A pending email-change record is created. 4. Supabase Auth updateUser({email:newEmail}) sends verification to the new email only. 5. Current email remains active. 6. Verification callback validates the Supabase email_change token within 24 hours. 7. Callback confirms the Auth user now has the new email. 8. Old email is inserted into parent_email_history and request is marked verified. 9. Sessions are refreshed; new email becomes login/invoice email immediately. 10. A reconciliation action completes archival if Auth changed but callback persistence was interrupted. Soft delete: 1. Parent reviews retained-data warning and enters current password plus DELETE confirmation. 2. Server reauthenticates. 3. In one platform transaction, set deleted status/timestamps, revoke platform sessions and write audit/outbox events. 4. Sign the browser out and show the deleted-account confirmation. 5. Subsequent platform access is denied. | S4: Wrong current password: reject and throttle without changing credentials. New password invalid or unchanged: show policy error. New email already used: reject without revealing unrelated account details. Verification link expired after 24 hours: current email remains active; allow a new request. Pending request replaced: cancel the old request before creating the new one. Verification callback replayed: return the already-completed result without duplicating email history. Auth email changed but archival write failed: reconciliation finalizes the pending request idempotently. Soft deletion with active sessions: revoke them all. Soft-deleted login: authenticate only at Supabase if applicable, then platform immediately denies and signs out. Restore request by parent: deny and direct to support. Admin restoration: reactivate profile but do not restore old sessions. | T4: Current password; new password and confirmation; proposed email; Supabase Auth user ID/current email; email-change token; typed deletion confirmation; optional deletion reason. | U4: Updated Auth password or email; archived prior email; email-change request status; soft-deleted/restored profile status; revoked sessions; audit and outbox events; refreshed invoice-delivery email. | V4: Account Settings → Security must show current verified email and actions for Change password, Change email and Delete account. Password form requires current/new/confirm fields and show/hide controls. Email-change form explains that the old email remains active until verification and that the link expires in 24 hours. Pending-email state shows proposed address, expiry time, Resend and Cancel. Delete flow uses a high-friction confirmation screen, retained-data explanation, current password and exact DELETE text. Deleted accounts see no normal dashboard. All screens are keyboard accessible, responsive at 320px and preserve non-sensitive inputs on retry. | W4: GET /v1/account/security POST /v1/account/password/change POST /v1/account/email-change/request POST /v1/account/email-change/resend POST /v1/account/email-change/cancel GET /auth/email-change/callback POST /v1/account/soft-delete POST /v1/admin/accounts/{parentId}/restore Use Supabase signInWithPassword for immediate current-password reauthentication. Use updateUser({email}) with Secure Email Change disabled and email OTP expiry 86400. The callback verifies type='email_change', completes archive/history state and refreshes the session. Every write endpoint is idempotent or protected by request/state constraints. | X4: profiles additions: - deleted_at timestamptz null - deleted_by_user_id uuid null - auth_revoked_before timestamptz null email_change_requests: - id uuid primary key - parent_user_id uuid not null references profiles(id) - old_email text not null - new_email text not null - status text not null: pending, verified, expired, cancelled - requested_at timestamptz not null - expires_at timestamptz not null - verified_at timestamptz null - cancelled_at timestamptz null - supabase_request_nonce text null - unique partial index: one pending request per parent parent_email_history: - id uuid primary key - parent_user_id uuid not null references profiles(id) - email text not null - archived_at timestamptz not null - reason text not null default 'email_changed' Use existing platform session tables/outbox/audit tables. Do not physically delete rows. | Y4: Passwords and verification tokens must never be logged or stored. Current-password reauthentication uses an isolated no-persist client and discards the password immediately. Email-change callbacks validate redirect origin, token type, request ownership and expiry. Old and new emails are personal data; mask them in general logs. Soft-delete endpoint is CSRF-protected, rate-limited and requires current password plus exact confirmation. All protected middleware checks account_status and auth_revoked_before. Admin restoration requires platform_admin authorization and a mandatory reason. Archive records and audit events are append-only. | Z4: Security settings load p95 under 1.5 seconds. Credential-change request p95 under 2 seconds excluding email delivery. Email-change expiry is exactly 24 hours based on server timestamps. No duplicate pending request or archived-email row from callback replay. Soft-delete access denial becomes effective on the next platform request. All sensitive screens meet WCAG keyboard/focus requirements. | AA4: AC1 Active parent can view current verified login email. AC2 Current password is required for password change, email change and soft delete. AC3 Successful password change invalidates the old password. AC4 New email remains inactive until verification. AC5 Email-change verification expires after 24 hours. AC6 Successful verification immediately activates the new email. AC7 Old email is archived exactly once after activation. AC8 Expired/cancelled request leaves old email active. AC9 Invoice and receipt delivery uses the newly verified email. AC10 Soft deletion retains all database records. AC11 Soft deletion revokes platform/app sessions and blocks access. AC12 Deleted accounts cannot self-restore. AC13 Authorized admin can restore status but not sessions. AC14 Replayed requests/callbacks remain idempotent. AC15 Passwords and verification tokens never appear in logs or platform tables. | AB4: IA-001; IA-002; Supabase email auth settings; platform session revocation; audit/outbox infrastructure; Billing integration event; administrator authorization. | AC4: Not a gamification feature; it is a required account-control and trust foundation. | AD4: https://supabase.com/docs/reference/javascript/auth-updateuser https://supabase.com/docs/reference/javascript/auth-resend https://supabase.com/docs/guides/local-development/cli/config | AE4: Configure Supabase Auth with secure email change disabled and email link/OTP expiry 86400 seconds. Use a pending-request table even though Supabase sends the email so the product can show state, expiry, cancel/resend and archive the old email. Make callback completion and reconciliation idempotent. Use profile account_status plus auth_revoked_before as the authoritative platform access gate. Do not call auth.admin.deleteUser. Soft-delete transaction must revoke all Babysteps session records and emit account_soft_deleted. Admin restoration must require a reason and create a fresh login requirement. Exact build packet: CBS-IA-003 | AF4: AT-IA-003-01 through AT-IA-003-15 | AG4: 1.0 | AH4: Product Owner | AI4: 2026-07-30
A5: IA-004 | B5: EP-IDENTITY-01 | C5: Identity & Access | D5: Child Passkey Access | E5: Windows Hello and Apple passkey access for learners | F5: Nice to Have | G5: Approved | H5: Yes | I5: Backlog | J5: Functional | K5: Shared Contract | L5: Parent and Learner | M5: As a parent, I want to enroll a learner for passkey access on compatible Windows and Mac devices so that the child can enter Babysteps without using the parent's email and password. | N5: Babysteps may provide optional learner access using standards-based WebAuthn passkeys backed by the operating system platform authenticator. On Windows, the local verification experience may be Windows Hello PIN, face or fingerprint. On macOS, it may be Touch ID, device passcode or another Apple passkey flow. Babysteps shall never receive or store the operating-system PIN or biometric. A parent must authenticate and enroll the learner first. A successful passkey assertion creates only a restricted learner session and never grants parent, billing or administrative access. | O5: 1. This feature is Nice to Have and must not block Version 1 launch. 2. Use WebAuthn/passkeys, not a Babysteps-owned Windows or Mac PIN. 3. Enrollment requires an active verified parent, completed onboarding and recent current-password reauthentication. 4. The selected learner must be owned by the parent or explicitly shared with that parent through learner-level authorization, and must be active. 5. Registration and authentication occur only on the central account origin. 6. Production RP ID is account.babysteps.in; production origin is https://account.babysteps.in. Local/preview environments use separately configured valid RP IDs/origins. 7. Registration requests authenticatorAttachment='platform', residentKey='required', userVerification='required' and attestation='none'. 8. Server challenges are random, single-use and expire after five minutes. 9. Store only WebAuthn credential material and metadata; never store PINs, biometric templates or platform secrets. 10. One learner may have multiple active passkeys; every credential can be individually named and revoked by an authorized parent. 11. Successful authentication creates a learner-only session scoped to the selected learner. 12. Learner passkey sessions cannot access parent account settings, billing, learner-management administration or another learner. 13. The one-active-learner-session rule still applies. 14. If passkeys are unavailable, cancelled or fail, fallback is parent email/password login; do not create a custom child PIN here. 15. Apple passkeys may synchronize through iCloud Keychain; do not promise that a credential is restricted to one physical Mac. 16. Signature-counter anomalies are evaluated according to passkey behavior; zero/non-incrementing counters for synced passkeys are logged rather than automatically treated as cloning. | P5: IA-001 through IA-003, learner profiles, learner authorization, app-launch/session control and WebAuthn-capable HTTPS origins are implemented. | Q5: An authenticated parent enrolls a learner, or an enrolled learner selects Use passkey. | R5: Enrollment: 1. Parent signs in and reauthenticates with current password. 2. Parent selects an active learner they own or are authorized to manage. 3. Parent gives the credential a friendly label. 4. Server creates one-time registration options and stores a challenge. 5. Browser calls navigator.credentials.create through a WebAuthn library. 6. Windows Hello or Apple platform authenticator performs local user verification. 7. Server verifies challenge, origin, RP ID hash, attestation response and user-verification flag. 8. Store credential ID, public key, counter and metadata. 9. Show enrolled credential and revocation controls. Learner authentication: 1. Open central Child access screen. 2. Select learner profile. 3. Server creates authentication options limited to that learner's non-revoked credentials. 4. Browser calls navigator.credentials.get. 5. Platform authenticator performs local verification. 6. Server verifies challenge, origin, RP ID, signature, credential ownership and UV flag. 7. Update counter/last-used metadata. 8. Create or refresh only a restricted learner authentication session. 9. Continue to the unified launcher. LP-004 independently authorizes learning-session start and must never revoke or replace an ongoing learning session. | S5: Unsupported browser/platform: hide or disable enrollment and explain fallback. User cancels OS prompt: return to learner selection without creating a session. Challenge expired/used: issue a fresh challenge. Unknown/revoked credential: deny. Credential belongs to another learner: deny and audit. Origin/RP mismatch or signature failure: deny and security-log. Counter anomaly: apply passkey-aware policy and log; do not incorrectly reject synced credentials solely for zero counter. Parent account is suspended or soft deleted: deny passkey use and revoke related authentication sessions. Lost device: parent revokes the credential from account settings. No enrolled credential: require parent login. Multiple matching credentials: allow the browser/platform chooser. | T5: Parent session and password reauthentication; learner ID; credential friendly label; WebAuthn registration/response objects; authentication assertion; server challenge; configured RP ID/origin. | U5: Stored learner passkey credential; registration/authentication audit events; restricted learner authentication session; updated credential usage metadata; revocation state. | V5: Add parent-facing Learner access settings with Enroll passkey and credential list/revoke controls. Add a central Child access page with learner selection and Use passkey. Use neutral wording such as 'Use device passkey'; platform-specific helper text may say Windows Hello or Touch ID when detected. Never ask for or display a Babysteps PIN field. Show compatibility/fallback messaging. Warn parents that Apple passkeys may sync across their Apple devices. Ensure keyboard accessibility, clear focus, cancel handling and 320px responsive behavior. | W5: POST /v1/learner-passkeys/registration/options POST /v1/learner-passkeys/registration/verify POST /v1/learner-passkeys/authentication/options POST /v1/learner-passkeys/authentication/verify GET /v1/learner-passkeys?learnerId= DELETE /v1/learner-passkeys/{credentialId} Use @simplewebauthn/server and @simplewebauthn/browser or an equivalent standards-conformant, locked dependency. Registration and verification are server-side authoritative. Successful authentication creates only a restricted learner authentication session rather than a parent Supabase Auth session. Starting a learning session is a separate LP-004 operation and cannot replace an ongoing session. | X5: learner_passkey_credentials: - id uuid primary key - learner_id uuid not null - created_by_parent_user_id uuid not null - credential_id text/base64url not null unique - public_key text/base64url not null - sign_count bigint not null default 0 - transports jsonb null - aaguid text null - backup_eligible boolean null - backup_state boolean null - friendly_name text not null - created_at timestamptz not null - last_used_at timestamptz null - revoked_at timestamptz null - revoked_by_parent_user_id uuid null webauthn_challenges: - id uuid primary key - purpose text: register or authenticate - parent_user_id uuid null - learner_id uuid not null - challenge_hash text not null - expires_at timestamptz not null - used_at timestamptz null - created_at timestamptz not null Add indexes on learner active credentials and challenge expiry. | Y5: Use HTTPS outside localhost. Validate challenge, origin, RP ID hash, signature, credential ownership and userVerification=true. Attestation preference is none. Store no operating-system PIN or biometric data. Challenges are hashed, single-use and five-minute expiry. Enrollment requires recent parent-password reauthentication and CSRF protection. Learner session permissions are least privilege. Credential lists reveal only friendly label and safe metadata. Rate-limit options/verification endpoints. Deny credential use when the owning parent account is suspended or soft deleted, or when the credential itself is revoked. Audit suspicious assertions without logging raw credential responses unnecessarily. | Z5: Passkey options endpoints p95 under 1 second. Verification p95 under 1.5 seconds excluding OS UI time. Support current WebAuthn-capable browsers on Windows and macOS as an optional compatibility target. No launch dependency if unsupported. Credential verification is deterministic and covered by contract tests. Accessibility and fallback flows remain usable without passkeys. | AA5: AC1 Only an authenticated reauthenticated parent can enroll. AC2 Parent can enroll a passkey for an owned active learner. AC3 Windows Hello-compatible platform authenticator can complete WebAuthn registration/authentication. AC4 macOS Apple passkey/Touch ID-compatible platform authenticator can complete WebAuthn registration/authentication. AC5 Babysteps never receives or stores PIN/biometric data. AC6 Authentication requires user verification. AC7 Credential cannot authenticate another learner. AC8 Successful assertion creates only a restricted learner authentication session and does not start or replace a learning session. AC9 Parent/billing/admin routes are denied to learner session. AC10 Challenge replay/expiry is rejected. AC11 Parent can list, label and revoke each credential. AC12 Revoked credential cannot authenticate. AC13 Unsupported/cancelled flow falls back to parent login. AC14 Synced Apple passkeys are not falsely described as one-Mac-only. AC15 Feature absence does not block Version 1 core flows. | AB5: IA-001 to IA-003; learner-profile requirements; active learner-session control; unified launcher; HTTPS/custom domain; WebAuthn library; browser compatibility testing. | AC5: Comparable to frictionless re-entry in learning apps, but implemented as a secure optional device capability rather than a proprietary child PIN. | AD5: https://learn.microsoft.com/en-us/windows/apps/develop/security/implement https://developer.apple.com/passkeys/ https://developer.apple.com/documentation/authenticationservices/supporting-passkeys | AE5: Implement one cross-platform WebAuthn passkey feature rather than separate Windows and Mac authentication systems. Use the central account origin and a configured RP ID. Require platform authenticator and user verification. Do not call the feature a Windows PIN in the data/API model. Create restricted learner sessions only. Keep all passkey code feature-flagged and optional. Test Windows Hello and macOS Safari/Chrome manually in addition to automated WebAuthn fixtures. Exact build packet: CBS-IA-004 | AF5: AT-IA-004-01 through AT-IA-004-15 | AG5: 1.0 | AH5: Product Owner | AI5: 2026-07-30
A6: HH-001 | B6: EP-HOUSEHOLD-FUTURE | C6: Deferred Architecture | D6: Household Entity | E6: Separate household entity and membership boundary | F6: Nice to Have | G6: Deferred | H6: No | I6: Deferred | J6: Functional | K6: Babysteps Platform | L6: Parent and Platform Administrator | M6: As a future platform operator, I may need a shared family entity that exists independently of any one parent so multiple adults and shared services can be managed under one stable boundary. | N6: In a future release, Babysteps may introduce a separate household entity with household membership records. Version 1 shall not create, read, require or expose a household entity. Parent profile UUIDs remain the direct ownership root for learners and subscriptions until this requirement is reactivated. | O6: Deferred scope includes: 1. households table and stable household_id. 2. household_members table. 3. owner/member/viewer membership roles. 4. automatic or explicit household creation. 5. household status and lifecycle. 6. parent membership in one or more households. 7. migration of existing parent-owned learners into a household. 8. household-level authorization and audit rules. Version 1 rules: - Do not create household tables. - Do not add household_id to learners, subscriptions, entitlements, passkeys or progress. - Do not show household onboarding. - Do not make current features depend on this deferred concept. | P6: A proven future need exists for a shared family entity that cannot be represented safely by direct parent ownership and learner-level permissions. | Q6: A formal architecture decision reactivates the deferred household epic. | R6: No Version 1 flow. Future design must include migration of existing parent-owned records without breaking stable learner IDs, subscription history or access controls. | S6: Until reactivated, requests for household creation or membership return no route because the feature does not exist. Future migration must define duplicate-family resolution, ownership conflicts and rollback. | T6: Future household name/status; membership invitations; existing parent, learner and subscription ownership records. | U6: Future household record and membership relationships. | V6: No Version 1 UI. A future release may add Family settings only after the underlying ownership and migration model is approved. | W6: No Version 1 API. Future API surface must be separately specified and versioned. | X6: No Version 1 tables or columns. Future implementation must include an explicit migration plan from owner_parent_id and purchaser_parent_id. | Y6: Do not infer family relationships from email domains, phone numbers, surnames or shared devices. Future membership must be explicit and audited. | Z6: Must not add query joins or latency to Version 1 while deferred. Future migration must preserve current IDs and data integrity. | AA6: AC1 No household table or household_id exists in Version 1. AC2 Learners remain keyed by owner_parent_id. AC3 Subscriptions remain keyed by purchaser_parent_id. AC4 Deferred scope does not affect current onboarding or launch. | AB6: Direct parent ownership architecture; learner ownership; purchaser-parent subscription model. | AC6: None; deferred architecture only. | AE6: Do not implement. Keep this row for future product/architecture review. Reactivation requires a new decision, versioned requirement and complete Codex build packet. | AG6: 0.1-deferred | AH6: Product Owner | AI6: 2026-07-30
A7: HH-002 | B7: EP-HOUSEHOLD-FUTURE | C7: Deferred Architecture | D7: Household Roles | E7: Household-wide guardian roles and ownership transfer | F7: Nice to Have | G7: Deferred | H7: No | I7: Deferred | J7: Functional | K7: Babysteps Platform | L7: Parent, Guardian and Platform Administrator | M7: As a future family administrator, I may want multiple adults to share authority over an entire family group and transfer household ownership. | N7: Household-wide adult membership, owner roles, ownership transfer and family-wide permissions are deferred. Version 1 may later support explicit learner-level guardian access, but that must not imply or create a household-wide role. | O7: Deferred scope includes: 1. inviting an adult to the whole household. 2. household owner, guardian and viewer roles. 3. ownership transfer. 4. final-owner protection. 5. whole-family access revocation. 6. household-wide reporting permissions. 7. adult membership across multiple households. Version 1: - Additional-adult access, if approved, is granted per learner. - A guardian cannot automatically see every learner owned by another parent. - No household owner role exists. | P7: A future use case requires the same adult permissions to apply automatically to every current and future learner in a shared family entity. | Q7: The household entity requirement is reactivated and a role/permission matrix is approved. | R7: No Version 1 household invitation or ownership-transfer flow. | S7: Future flows must handle expired invitations, duplicate accounts, final-owner protection, conflicting ownership and access removal. | T7: Future invitee email; membership role; household ID; ownership-transfer confirmation. | U7: Future household membership and authorization records. | V7: No Version 1 household-member UI. Learner-level sharing remains a separate requirement. | W7: No Version 1 household membership APIs. | X7: No household_members or household_invites tables in Version 1. | Y7: Future roles must use least privilege, explicit consent, auditable invitations and cross-family isolation. | Z7: No Version 1 runtime dependency. Future role checks must remain centrally testable and deterministic. | AA7: AC1 No household-wide role exists in Version 1. AC2 Learner-level sharing does not grant implicit access to other learners. AC3 Ownership transfer is unavailable until reactivated. | AB7: HH-001 deferred household entity; future learner guardian requirements. | AC7: None; deferred collaboration model. | AE7: Do not implement. Any future activation requires exact role definitions, invitation expiry, ownership-transfer rules, authorization matrix and Codex packet. | AG7: 0.1-deferred | AH7: Product Owner | AI7: 2026-07-30
A8: HH-003 | B8: EP-HOUSEHOLD-FUTURE | C8: Deferred Architecture | D8: Household Billing | E8: Household-owned subscriptions and shared family billing | F8: Nice to Have | G8: Deferred | H8: No | I8: Deferred | J8: Functional | K8: Babysteps Platform | L8: Paying Parent and Platform Administrator | M8: As a future family account, I may want one jointly owned subscription and billing relationship that is independent of the individual purchaser. | N8: Household-owned subscriptions, shared family billing ownership and transfer of the commercial counterparty are deferred. In Version 1, every subscription belongs to the paying parent through purchaser_parent_id, is assigned to exactly one learner through assigned_learner_id, and may represent either one app or a bundle of apps. | O8: Deferred scope includes: 1. household_id as subscription owner. 2. multiple billing administrators. 3. transfer of billing ownership between adults. 4. household-level payment methods. 5. shared invoice access. 6. family-wide plan administration independent of purchaser. 7. migration from purchaser_parent_id to household ownership. Version 1: - purchaser_parent_id and assigned_learner_id are mandatory. - The paying parent is the commercial counterparty. - Individual-app and bundle entitlements apply only to the subscription's assigned learner without changing commercial ownership. - Additional guardians receive no billing access unless separately and explicitly approved. | P8: A future commercial model requires joint family ownership or transfer of subscriptions without keeping the purchaser as the legal/account owner. | Q8: Billing strategy approves household ownership and the household entity is reactivated. | R8: No Version 1 household billing flow. | S8: Future design must handle payment-method ownership, invoice access, refunds, tax identity, ownership transfer and disputes. | T8: Future household ID; billing-administrator roles; subscription/payment records. | U8: Future household-owned subscription and billing authority. | V8: No household billing UI in Version 1. | W8: No household-owned billing API in Version 1. | X8: Subscriptions continue to use purchaser_parent_id and assigned_learner_id; do not add household_id. Product definitions determine whether the subscription grants one app or a bundle of apps. | Y8: Billing access is restricted to the purchaser parent and authorized platform support. Financial records remain auditable and retained. | Z8: No Version 1 impact. Future migration must preserve invoice, payment, refund and entitlement history. | AA8: AC1 Every Version 1 subscription has purchaser_parent_id and assigned_learner_id. AC2 One subscription covers exactly one learner. AC3 No household_id exists on subscriptions. AC4 Individual-app subscriptions grant one app; bundle subscriptions grant all included apps to the assigned learner. AC5 Invoices remain associated with the paying parent's verified email. | AB8: Future household entity; billing and subscription requirements. | AC8: None; deferred commercial model. | AE8: Do not implement. Future activation requires legal/commercial ownership rules, billing authorization, migration design and a complete Codex packet. The active Version 1 rule remains one purchaser-parent subscription assigned to one learner. | AG8: 0.1-deferred | AH8: Product Owner | AI8: 2026-07-30
